<?xml version="1.0"?>

<!-- XML namespaces -->
<robot xmlns:sensor="http://playerstage.sourceforge.net/gazebo/xmlschema/#sensor"
       xmlns:controller="http://playerstage.sourceforge.net/gazebo/xmlschema/#controller"
       xmlns:interface="http://playerstage.sourceforge.net/gazebo/xmlschema/#interface"
       xmlns:xacro="http://ros.org/wiki/xacro">


  <xacro:include filename="$(find aero_description)/urdf/common.xacro" />
  <xacro:include filename="$(find aero_description)/common_urdf/gazebo.xacro" />

  <xacro:property name="wrist_sensor_offset" value="0.0"/>

  <xacro:macro name="aero_upper" params="base_link disable_mesh:=false r_hand_link:=r_hand_link l_hand_link:=l_hand_link">
  <!-- ============================   aero(typeF_upper)   ============================ -->
  <link name="${base_link}">
    <inertial>
<!--
        <mass value="0.82" />
        <origin xyz="-0.002 0.0 0.0" rpy="0 0 0"/>
        <inertia ixx="0.003" ixy="0.0" ixz="0.0" iyy="0.002" iyz="0.0" izz="0.005"/>
-->
        <mass value="0.001" />
        <origin xyz="0.0 0.0 0.0" rpy="0 0 0"/>
        <inertia ixx="0.0" ixy="0.0" ixz="0.0" iyy="0.0" iyz="0.0" izz="0.0"/>

    </inertial>
  </link>
  <xacro:gazebo_link_reference link_name="${base_link}" />

  <link name="hip_sphere_link">
    <xacro:unless value="${disable_mesh}"> <visual>
      <origin xyz="0 0 0" rpy="0 -0 0"/>
      <geometry>
        <mesh filename="package://aero_description/meshes/typeF_upperbody/WAIST_LINK1_mesh.dae" scale="1 1 1" />
      </geometry>
    </visual> </xacro:unless>
    <xacro:unless value="${disable_mesh}"> <collision>
      <origin xyz="0 0 0" rpy="0 -0 0"/>
      <geometry>
        <mesh filename="package://aero_description/meshes/typeF_upperbody/WAIST_LINK1_mesh.dae" scale="1 1 1" />
      </geometry>
    </collision> </xacro:unless>
    <inertial>
      <mass value="1.105" />
      <origin xyz="0.001 0.0 0.064" rpy="0 -0 0"/>
      <inertia ixx="0.0026" ixy="0" ixz="0" iyy="0.0026" iyz="0" izz="0.0013"/>
    </inertial>
  </link>
  <xacro:gazebo_link_reference link_name="hip_sphere_link" />

  <link name="hip_center">
    <inertial>
      <mass value="0.012" />
      <origin xyz="0.0 0.0 0.0" rpy="0 -0 0"/>
      <inertia ixx="0.0" ixy="0" ixz="0" iyy="0.0" iyz="0" izz="0.0"/>
    </inertial>
  </link>
  <xacro:gazebo_link_reference link_name="hip_center" />

  <link name="body_link">
    <xacro:unless value="${disable_mesh}"> <visual>
      <origin xyz="0 0 0" rpy="0 -0 0"/>
      <geometry>
        <mesh filename="package://aero_description/meshes/typeF_upperbody/WAIST_LINK3_mesh.dae" scale="1 1 1" />
      </geometry>
    </visual> </xacro:unless>
    <xacro:unless value="${disable_mesh}"> <collision>
      <origin xyz="0 0 0" rpy="0 -0 0"/>
      <geometry>
        <mesh filename="package://aero_description/meshes/typeF_upperbody/WAIST_LINK3_mesh.dae" scale="1 1 1" />
      </geometry>
    </collision> </xacro:unless>
    <inertial>
      <mass value="6.7" />
      <origin xyz="0.001 0 0.197" rpy="0 -0 0"/>
<!--
      <inertia ixx="0.334" ixy="0" ixz="0.0035" iyy="0.308" iyz="0.0001" izz="0.0497"/>
-->
      <inertia ixx="0.07378" ixy="0" ixz="0.0044" iyy="0.048" iyz="0.0001" izz="0.0497"/>
    </inertial>
  </link>
  <xacro:gazebo_link_reference link_name="body_link" />

  <link name="l_shoulder_link">
    <xacro:unless value="${disable_mesh}"> <visual>
      <origin xyz="0 0 0" rpy="-0.174532925 -0 0"/>
      <geometry>
        <mesh filename="package://aero_description/meshes/typeF_upperbody/LARM_LINK1_mesh.dae" scale="1 1 1" />
      </geometry>
    </visual> </xacro:unless>
    <xacro:unless value="${disable_mesh}"> <collision>
      <origin xyz="0 0 0" rpy="-0.174532925 -0 0"/>
      <geometry>
        <mesh filename="package://aero_description/meshes/typeF_upperbody/LARM_LINK1_mesh.dae" scale="1 1 1" />
      </geometry>
    </collision> </xacro:unless>
    <inertial>
      <mass value="0.738" />
      <origin xyz="-0.0001 -0.0499 0.0044" rpy="0 -0 0"/>
      <inertia ixx="0.002" ixy="0" ixz="0" iyy="0.0003" iyz="0.0002" izz="0.0019"/>
    </inertial>
  </link>
  <xacro:gazebo_link_reference link_name="l_shoulder_link" />

  <link name="l_shoulder_center">
    <xacro:unless value="${disable_mesh}"> <visual>
      <origin xyz="0 0 0" rpy="0 -0 0"/>
      <geometry>
        <mesh filename="package://aero_description/meshes/typeF_upperbody/LARM_LINK2_mesh.dae" scale="1 1 1" />
      </geometry>
    </visual> </xacro:unless>
    <xacro:unless value="${disable_mesh}"> <collision>
      <origin xyz="0 0 0" rpy="0 -0 0"/>
      <geometry>
        <mesh filename="package://aero_description/meshes/typeF_upperbody/LARM_LINK2_mesh.dae" scale="1 1 1" />
      </geometry>
    </collision> </xacro:unless>
    <inertial>
      <mass value="0.834" />
      <origin xyz="-0.0007 -0.0093 -0.0768" rpy="0 -0 0"/>
      <inertia ixx="0.0011" ixy="0" ixz="0.0" iyy="0.0011" iyz="0" izz="0.0004"/>
    </inertial>
  </link>
  <xacro:gazebo_link_reference link_name="l_shoulder_center" />

  <link name="l_upperarm_link">
    <xacro:unless value="${disable_mesh}"> <visual>
      <origin xyz="0 0 0" rpy="0 -0 0"/>
      <geometry>
        <mesh filename="package://aero_description/meshes/typeF_upperbody/LARM_LINK3_mesh.dae" scale="1 1 1" />
      </geometry>
    </visual> </xacro:unless>
    <xacro:unless value="${disable_mesh}"> <collision>
      <origin xyz="0 0 0" rpy="0 -0 0"/>
      <geometry>
        <mesh filename="package://aero_description/meshes/typeF_upperbody/LARM_LINK3_mesh.dae" scale="1 1 1" />
      </geometry>
    </collision> </xacro:unless>
    <inertial>
      <mass value="0.852" />
      <origin xyz="-0.0099 0 -0.0496" rpy="0 -0 0"/>
      <inertia ixx="0.0015" ixy="0" ixz="0.0001" iyy="0.0016" iyz="0" izz="0.0005"/>
    </inertial>
  </link>
  <xacro:gazebo_link_reference link_name="l_upperarm_link" />

  <link name="l_elbow_link">
    <xacro:unless value="${disable_mesh}"> <visual>
      <origin xyz="-0.035 0 -0.035" rpy="0 -0 0"/>
      <geometry>
        <mesh filename="package://aero_description/meshes/typeF_upperbody/LARM_LINK4_mesh.dae" scale="1 1 1" />
      </geometry>
    </visual> </xacro:unless>
    <xacro:unless value="${disable_mesh}"> <collision>
      <origin xyz="-0.035 0 -0.035" rpy="0 -0 0"/>
      <geometry>
        <mesh filename="package://aero_description/meshes/typeF_upperbody/LARM_LINK4_mesh.dae" scale="1 1 1" />
      </geometry>
    </collision> </xacro:unless>
    <inertial>
      <mass value="0.251" />
      <origin xyz="-0.0422 -0.0002 -0.0061" rpy="0 -0 0"/>
      <inertia ixx="0.0005" ixy="0" ixz="0.0001" iyy="0.0005" iyz="0" izz="0.0002"/>
    </inertial>
  </link>
  <xacro:gazebo_link_reference link_name="l_elbow_link" />

  <link name="l_forearm_link">
    <xacro:unless value="${disable_mesh}"> <visual>
      <origin xyz="0 0 0" rpy="0 0 -1.5707963267948966"/>
      <geometry>
        <mesh filename="package://aero_description/meshes/typeF_upperbody/LARM_LINK5_mesh.dae" scale="1 1 1" />
      </geometry>
    </visual> </xacro:unless>
    <xacro:unless value="${disable_mesh}"> <collision>
      <origin xyz="0 0 0" rpy="0 0 -1.5707963267948966"/>
      <geometry>
        <mesh filename="package://aero_description/meshes/typeF_upperbody/LARM_LINK5_mesh.dae" scale="1 1 1" />
      </geometry>
    </collision> </xacro:unless>
    <inertial>
      <mass value="0.91" />
      <origin xyz="0.0 0.0018 -0.0754" rpy="0 -0 0"/>
      <inertia ixx="0.0022" ixy="0" ixz="0" iyy="0.0023" iyz="0" izz="0.0004"/>
    </inertial>
  </link>
  <xacro:gazebo_link_reference link_name="l_forearm_link" />

  <link name="l_wrist_center">
    <inertial>
      <mass value="0.005" />
      <origin xyz="0 -0.0019 0" rpy="0 -0 0"/>
      <inertia ixx="0.0" ixy="0" ixz="0" iyy="0.0" iyz="0" izz="0.0"/>
    </inertial>
  </link>
  <xacro:gazebo_link_reference link_name="l_wrist_center" />

  <link name="neck_link">
    <xacro:unless value="${disable_mesh}"> <visual>
      <origin xyz="0 0 0" rpy="0 -0 0"/>
      <geometry>
        <mesh filename="package://aero_description/meshes/typeF_upperbody/NECK_LINK1_mesh.dae" scale="1 1 1" />
      </geometry>
    </visual> </xacro:unless>
    <xacro:unless value="${disable_mesh}"> <collision>
      <origin xyz="0 0 0" rpy="0 -0 0"/>
      <geometry>
        <mesh filename="package://aero_description/meshes/typeF_upperbody/NECK_LINK1_mesh.dae" scale="1 1 1" />
      </geometry>
    </collision> </xacro:unless>
    <inertial>
      <mass value="0.275" />
      <origin xyz="-0.0003 0.0003 0.0439" rpy="0 -0 0"/>
      <inertia ixx="0.0002" ixy="0" ixz="0" iyy="0.0002" iyz="0" izz="0.0001"/>
    </inertial>
  </link>
  <xacro:gazebo_link_reference link_name="neck_link" />

  <link name="head_base_link">
    <xacro:unless value="${disable_mesh}"> <visual>
      <origin xyz="0 0 0" rpy="0 -0 0"/>
      <geometry>
        <mesh filename="package://aero_description/meshes/typeF_upperbody/NECK_LINK2_mesh.dae" scale="1 1 1" />
      </geometry>
    </visual> </xacro:unless>
    <xacro:unless value="${disable_mesh}"> <collision>
      <origin xyz="0 0 0" rpy="0 -0 0"/>
      <geometry>
        <mesh filename="package://aero_description/meshes/typeF_upperbody/NECK_LINK2_mesh.dae" scale="1 1 1" />
      </geometry>
    </collision> </xacro:unless>
    <inertial>
      <mass value="0.005" />
      <origin xyz="0 -0.0019 0" rpy="0 -0 0"/>
      <inertia ixx="0.00" ixy="0" ixz="0" iyy="0.0005" iyz="0" izz="0.0"/>
    </inertial>
  </link>
  <xacro:gazebo_link_reference link_name="head_base_link" />

  <link name="head_link">
    <xacro:unless value="${disable_mesh}"> <visual>
      <origin xyz="0 0 0" rpy="0 -0 0"/>
      <geometry>
        <mesh filename="package://aero_description/meshes/typeF_upperbody/NECK_LINK3_mesh.dae" scale="1 1 1" />
      </geometry>
    </visual> </xacro:unless>
    <xacro:unless value="${disable_mesh}"> <collision>
      <origin xyz="0 0 0" rpy="0 -0 0"/>
      <geometry>
        <mesh filename="package://aero_description/meshes/typeF_upperbody/NECK_LINK3_mesh.dae" scale="1 1 1" />
      </geometry>
    </collision> </xacro:unless>
    <inertial>
      <mass value="0.685" />
      <origin xyz="0.0047 0 0.0711" rpy="0 -0 0"/>
      <inertia ixx="0.0018" ixy="0" ixz="0.0001" iyy="0.0017" iyz="0" izz="0.0014"/>
    </inertial>
  </link>
  <xacro:gazebo_link_reference link_name="head_link" />

  <link name="r_shoulder_link">
    <xacro:unless value="${disable_mesh}"> <visual>
      <origin xyz="0 0 0" rpy="0.174532925 -0 0"/>
      <geometry>
        <mesh filename="package://aero_description/meshes/typeF_upperbody/RARM_LINK1_mesh.dae" scale="1 1 1" />
      </geometry>
    </visual> </xacro:unless>
    <xacro:unless value="${disable_mesh}"> <collision>
      <origin xyz="0 0 0" rpy="0.174532925 -0 0"/>
      <geometry>
        <mesh filename="package://aero_description/meshes/typeF_upperbody/RARM_LINK1_mesh.dae" scale="1 1 1" />
      </geometry>
    </collision> </xacro:unless>
    <inertial>
      <mass value="0.738" />
      <origin xyz="0.0001 0.0499 0.0044" rpy="0 -0 0"/>
      <inertia ixx="0.002" ixy="0" ixz="0" iyy="0.0003" iyz="0.0002" izz="0.0019"/>
    </inertial>
  </link>
  <xacro:gazebo_link_reference link_name="r_shoulder_link" />

  <link name="r_shoulder_center">
    <xacro:unless value="${disable_mesh}"> <visual>
      <origin xyz="0 0 0" rpy="0 -0 0"/>
      <geometry>
        <mesh filename="package://aero_description/meshes/typeF_upperbody/RARM_LINK2_mesh.dae" scale="1 1 1" />
      </geometry>
    </visual> </xacro:unless>
    <xacro:unless value="${disable_mesh}"> <collision>
      <origin xyz="0 0 0" rpy="0 -0 0"/>
      <geometry>
        <mesh filename="package://aero_description/meshes/typeF_upperbody/RARM_LINK2_mesh.dae" scale="1 1 1" />
      </geometry>
    </collision> </xacro:unless>
    <inertial>
      <mass value="0.834" />
      <origin xyz="-0.0007 0.0096 -0.0768" rpy="0 -0 0"/>
      <inertia ixx="0.0011" ixy="0" ixz="0" iyy="0.0011" iyz="0" izz="0.0004"/>
    </inertial>
  </link>
  <xacro:gazebo_link_reference link_name="r_shoulder_center" />

  <link name="r_upperarm_link">
    <xacro:unless value="${disable_mesh}"> <visual>
      <origin xyz="0 0 0" rpy="0 -0 0"/>
      <geometry>
        <mesh filename="package://aero_description/meshes/typeF_upperbody/RARM_LINK3_mesh.dae" scale="1 1 1" />
      </geometry>
    </visual> </xacro:unless>
    <xacro:unless value="${disable_mesh}"> <collision>
      <origin xyz="0 0 0" rpy="0 -0 0"/>
      <geometry>
        <mesh filename="package://aero_description/meshes/typeF_upperbody/RARM_LINK3_mesh.dae" scale="1 1 1" />
      </geometry>
    </collision> </xacro:unless>
    <inertial>
      <mass value="0.852" />
      <origin xyz="-0.0099 0 -0.0496" rpy="0 -0 0"/>
      <inertia ixx="0.0015" ixy="0" ixz="0.0001" iyy="0.0016" iyz="0" izz="0.0005"/>
    </inertial>
  </link>
  <xacro:gazebo_link_reference link_name="r_upperarm_link" />

  <link name="r_elbow_link">
    <xacro:unless value="${disable_mesh}"> <visual>
      <origin xyz="-0.035 0 -0.035" rpy="0 -0 0"/>
      <geometry>
        <mesh filename="package://aero_description/meshes/typeF_upperbody/RARM_LINK4_mesh.dae" scale="1 1 1" />
      </geometry>
    </visual> </xacro:unless>
    <xacro:unless value="${disable_mesh}"> <collision>
      <origin xyz="-0.035 0 -0.035" rpy="0 -0 0"/>
      <geometry>
        <mesh filename="package://aero_description/meshes/typeF_upperbody/RARM_LINK4_mesh.dae" scale="1 1 1" />
      </geometry>
    </collision> </xacro:unless>
    <inertial>
      <mass value="0.251" />
      <origin xyz="-0.0422 -0.0002 -0.0061" rpy="0 -0 0"/>
      <inertia ixx="0.0005" ixy="0" ixz="0.0001" iyy="0.0005" iyz="0" izz="0.0002"/>
    </inertial>
  </link>
  <xacro:gazebo_link_reference link_name="r_elbow_link" />

  <link name="r_forearm_link">
    <xacro:unless value="${disable_mesh}"> <visual>
      <origin xyz="0 0 0" rpy="0 0 1.5707963267948966"/>
      <geometry>
        <mesh filename="package://aero_description/meshes/typeF_upperbody/RARM_LINK5_mesh.dae" scale="1 1 1" />
      </geometry>
    </visual> </xacro:unless>
    <xacro:unless value="${disable_mesh}"> <collision>
      <origin xyz="0 0 0" rpy="0 0 1.5707963267948966"/>
      <geometry>
        <mesh filename="package://aero_description/meshes/typeF_upperbody/RARM_LINK5_mesh.dae" scale="1 1 1" />
      </geometry>
    </collision> </xacro:unless>
    <inertial>
      <mass value="0.91" />
      <origin xyz="0.0 -0.0018 -0.0754" rpy="0 -0 0"/>
      <inertia ixx="0.0022" ixy="0" ixz="0" iyy="0.0023" iyz="0" izz="0.0004"/>
    </inertial>
  </link>
  <xacro:gazebo_link_reference link_name="r_forearm_link" />

  <link name="r_wrist_center">
    <inertial>
      <mass value="0.005" />
      <origin xyz="0 -0.0019 0" rpy="0 -0 0"/>
      <inertia ixx="0.0" ixy="0" ixz="0" iyy="0.0" iyz="0" izz="0.0"/>
    </inertial>
  </link>
  <xacro:gazebo_link_reference link_name="r_wrist_center" />

  <joint name="waist_y_joint" type="revolute">
    <parent link="${base_link}"/>
    <child  link="hip_sphere_link"/>
    <origin xyz="0 0 0.010" rpy="0 -0 0 "/>
    <axis   xyz="0 0 1"/>
    <!-- from -120 to 120 degrees-->
    <limit lower="-2.09" upper="2.09" effort="500" velocity="0.5" />
    <dynamics damping="0.2" friction="0" />
  </joint>
  <xacro:gazebo_transmission joint_name="waist_y_joint" />

  <joint name="waist_p_joint" type="revolute">
    <parent link="hip_sphere_link"/>
    <child  link="hip_center"/>
    <origin xyz="0 0 0.1355" rpy="0 -0 0 "/>
    <axis   xyz="0 1 0"/>
    <!-- from -5 to 35 degrees-->
    <limit lower="-0.087" upper="0.61" effort="2000" velocity="0.3" />
    <dynamics damping="0.2" friction="0" />
  </joint>
  <xacro:gazebo_transmission joint_name="waist_p_joint" />

  <joint name="waist_r_joint" type="revolute">
    <parent link="hip_center"/>
    <child  link="body_link"/>
    <origin xyz="0 0 0" rpy="0 -0 0 "/>
    <axis   xyz="1 0 0"/>
    <!-- from -1 to 1 degrees-->
    <limit lower="-0.017" upper="0.017" effort="2000" velocity="0.3" />
    <dynamics damping="0.2" friction="0" />
  </joint>
  <xacro:gazebo_transmission joint_name="waist_r_joint" />

  <joint name="l_shoulder_p_joint" type="revolute">
    <parent link="body_link"/>
    <child  link="l_shoulder_link"/>
    <origin xyz="-0.01815 0.1342 0.3049" rpy="0 -0 0 "/>
    <axis   xyz="0 0.984808 -0.173648"/>
    <!-- from -88 to 15 degrees-->
    <limit lower="-1.535" upper="0.261" effort="200" velocity="0.5" />
    <dynamics damping="0.2" friction="0" />
  </joint>
  <xacro:gazebo_transmission joint_name="l_shoulder_p_joint" />

  <joint name="l_shoulder_r_joint" type="revolute">
    <parent link="l_shoulder_link"/>
    <child  link="l_shoulder_center"/>
    <origin xyz="0 0.05978 0.028046" rpy="0 -0 0 "/>
    <axis   xyz="1 0 0"/>
    <!-- from 0 to 90 degrees-->
    <limit lower="0" upper="1.5707" effort="100" velocity="0.6" />
    <dynamics damping="0.2" friction="0" />
  </joint>
  <xacro:gazebo_transmission joint_name="l_shoulder_r_joint" />

  <joint name="l_shoulder_y_joint" type="revolute">
    <parent link="l_shoulder_center"/>
    <child  link="l_upperarm_link"/>
    <origin xyz="0 -0.010 -0.127" rpy="0 -0 0 "/>
    <axis   xyz="0 0 1"/>
    <!-- from -180 to 45 degrees-->
    <limit lower="-1.5707" upper="0.785398" effort="100" velocity="0.5" />
    <dynamics damping="0.2" friction="0" />
  </joint>
  <xacro:gazebo_transmission joint_name="l_shoulder_y_joint" />

  <joint name="l_elbow_joint" type="revolute">
    <parent link="l_upperarm_link"/>
    <child  link="l_elbow_link"/>
    <origin xyz="0.035 0 -0.1625" rpy="0 -0 0 "/>
    <axis   xyz="0 1 0"/>
    <!-- from -171 to 0 degrees-->
    <limit lower="-3.0" upper="0" effort="100" velocity="1.0" />
    <dynamics damping="0.2" friction="0" />
  </joint>
  <xacro:gazebo_transmission joint_name="l_elbow_joint" />

  <joint name="l_wrist_y_joint" type="revolute">
    <parent link="l_elbow_link"/>
    <child  link="l_forearm_link"/>
    <origin xyz="-0.035 0 -0.070" rpy="0 -0 0 "/>
    <axis   xyz="0 0 1"/>
    <!-- from -180 to 180 degrees-->
    <limit lower="-1.5707" upper="1.5707" effort="100" velocity="1.5" />
    <dynamics damping="0.2" friction="0" />
  </joint>
  <xacro:gazebo_transmission joint_name="l_wrist_y_joint" />

  <joint name="l_wrist_p_joint" type="revolute">
    <parent link="l_forearm_link"/>
    <child  link="l_wrist_center"/>
    <origin xyz="0 0 -0.1955" rpy="0 -0 0 "/>
    <axis   xyz="0 1 0"/>
    <!-- from -5 to 5 degrees-->
    <limit lower="-0.087" upper="0.087" effort="100" velocity="1.3" />
    <dynamics damping="0.2" friction="0" />
  </joint>
  <xacro:gazebo_transmission joint_name="l_wrist_p_joint" />

  <joint name="l_wrist_r_joint" type="revolute">
    <parent link="l_wrist_center"/>
    <child  link="${l_hand_link}"/>
    <origin xyz="0 0 0" rpy="0 -0 0 "/>
    <axis   xyz="1 0 0"/>
    <!-- from -85 to 25 degrees-->
    <limit lower="-1.484" upper="0.436" effort="100" velocity="1.3" />
    <dynamics damping="0.2" friction="0" />
  </joint>
  <xacro:gazebo_transmission joint_name="l_wrist_r_joint" />

  <joint name="neck_y_joint" type="revolute">
    <parent link="body_link"/>
    <child  link="neck_link"/>
    <origin xyz="0 0 0.3535" rpy="0 -0 0 "/>
    <axis   xyz="0 0 1"/>
    <!-- from -120 to 120 degrees-->
    <limit lower="-2.09" upper="2.09" effort="100" velocity="0.5" />
    <dynamics damping="0.2" friction="0" />
  </joint>
  <xacro:gazebo_transmission joint_name="neck_y_joint" />

  <joint name="neck_p_joint" type="revolute">
    <parent link="neck_link"/>
    <child  link="head_base_link"/>
    <origin xyz="0 0 0.1045" rpy="0 -0 0 "/>
    <axis   xyz="0 1 0"/>
    <!-- from -15 to 55 degrees-->
    <limit lower="-0.262" upper="0.96" effort="100" velocity="0.5" />
    <dynamics damping="0.2" friction="0" />
  </joint>
  <xacro:gazebo_transmission joint_name="neck_p_joint" />

  <joint name="neck_r_joint" type="revolute">
    <parent link="head_base_link"/>
    <child  link="head_link"/>
    <origin xyz="0 0 0" rpy="0 -0 0 "/>
    <axis   xyz="1 0 0"/>
    <!-- from -5 to 5 degrees-->
    <limit lower="-0.087" upper="0.087" effort="100" velocity="0.5" />
    <dynamics damping="0.2" friction="0" />
  </joint>
  <xacro:gazebo_transmission joint_name="neck_r_joint" />

  <joint name="r_shoulder_p_joint" type="revolute">
    <parent link="body_link"/>
    <child  link="r_shoulder_link"/>
    <origin xyz="-0.01815 -0.1342 0.3049" rpy="0 -0 0 "/>
    <axis   xyz="0 0.984808 0.173648"/>
    <!-- from -88 to 15 degrees-->
    <limit lower="-1.535" upper="0.261" effort="200" velocity="0.5" />
    <dynamics damping="0.2" friction="0" />
  </joint>
  <xacro:gazebo_transmission joint_name="r_shoulder_p_joint" />

  <joint name="r_shoulder_r_joint" type="revolute">
    <parent link="r_shoulder_link"/>
    <child  link="r_shoulder_center"/>
    <origin xyz="0 -0.059778 0.028046" rpy="0 -0 0 "/>
    <axis   xyz="1 0 0"/>
    <!-- from -90 to 0 degrees-->
    <limit lower="-1.5707" upper="0" effort="100" velocity="0.6" />
    <dynamics damping="0.2" friction="0" />
  </joint>
  <xacro:gazebo_transmission joint_name="r_shoulder_r_joint" />

  <joint name="r_shoulder_y_joint" type="revolute">
    <parent link="r_shoulder_center"/>
    <child  link="r_upperarm_link"/>
    <origin xyz="0 0.010 -0.127" rpy="0 -0 0 "/>
    <axis   xyz="0 0 1"/>
    <!-- from -45 to 180 degrees-->
    <limit lower="-0.785398" upper="1.5707" effort="100" velocity="0.5" />
    <dynamics damping="0.2" friction="0" />
  </joint>
  <xacro:gazebo_transmission joint_name="r_shoulder_y_joint" />

  <joint name="r_elbow_joint" type="revolute">
    <parent link="r_upperarm_link"/>
    <child  link="r_elbow_link"/>
    <origin xyz="0.035 0 -0.1625" rpy="0 -0 0 "/>
    <axis   xyz="0 1 0"/>
    <!-- from -171 to 0 degrees-->
    <limit lower="-3.0" upper="0" effort="100" velocity="1.0" />
    <dynamics damping="0.2" friction="0" />
  </joint>
  <xacro:gazebo_transmission joint_name="r_elbow_joint" />

  <joint name="r_wrist_y_joint" type="revolute">
    <parent link="r_elbow_link"/>
    <child  link="r_forearm_link"/>
    <origin xyz="-0.035 0 -0.070" rpy="0 -0 0 "/>
    <axis   xyz="0 0 1"/>
    <!-- from -180 to 180 degrees-->
    <limit lower="-1.5707" upper="1.5707" effort="100" velocity="1.5" />
    <dynamics damping="0.2" friction="0" />
  </joint>
  <xacro:gazebo_transmission joint_name="r_wrist_y_joint" />

  <joint name="r_wrist_p_joint" type="revolute">
    <parent link="r_forearm_link"/>
    <child  link="r_wrist_center"/>
    <origin xyz="0 0 -0.1955" rpy="0 -0 0 "/>
    <axis   xyz="0 1 0"/>
    <!-- from -5 to 5 degrees-->
    <limit lower="-0.087" upper="0.087" effort="100" velocity="1.3" />
    <dynamics damping="0.2" friction="0" />
  </joint>
  <xacro:gazebo_transmission joint_name="r_wrist_p_joint" />

  <joint name="r_wrist_r_joint" type="revolute">
    <parent link="r_wrist_center"/>
    <child  link="${r_hand_link}"/>
    <origin xyz="0 0 0" rpy="0 -0 0 "/>
    <axis   xyz="1 0 0"/>
    <!-- from -25 to 85 degrees-->
    <limit lower="-0.436" upper="1.484" effort="100" velocity="1.3" />
    <dynamics damping="0.2" friction="0" />
  </joint>
  <xacro:gazebo_transmission joint_name="r_wrist_r_joint" />
  </xacro:macro>
</robot>
