<?xml version="1.0"?>

<!-- XML namespaces -->
<robot xmlns:xi="http://www.w3.org/2001/XInclude"
       xmlns:gazebo="http://playerstage.sourceforge.net/gazebo/xmlschema/#gz"
       xmlns:model="http://playerstage.sourceforge.net/gazebo/xmlschema/#model"
       xmlns:sensor="http://playerstage.sourceforge.net/gazebo/xmlschema/#sensor"
       xmlns:body="http://playerstage.sourceforge.net/gazebo/xmlschema/#body"
       xmlns:geom="http://playerstage.sourceforge.net/gazebo/xmlschema/#geom"
       xmlns:joint="http://playerstage.sourceforge.net/gazebo/xmlschema/#joint"
       xmlns:interface="http://playerstage.sourceforge.net/gazebo/xmlschema/#interface"
       xmlns:rendering="http://playerstage.sourceforge.net/gazebo/xmlschema/#rendering"
       xmlns:renderable="http://playerstage.sourceforge.net/gazebo/xmlschema/#renderable"
       xmlns:controller="http://playerstage.sourceforge.net/gazebo/xmlschema/#controller"
       xmlns:physics="http://playerstage.sourceforge.net/gazebo/xmlschema/#physics"
       xmlns:xacro="http://ros.org/wiki/xacro">

  <xacro:include filename="$(find aero_description)/urdf/common.xacro" />
  <xacro:include filename="$(find aero_description)/common_urdf/gazebo.xacro" />

  <xacro:macro name="lifter" params="base_link">
  <!-- ============================   aero(typeC_lifter)   ============================ -->
    <link name="${base_link}">
      <visual>
        <origin xyz="0 0 0" rpy="0 -0 0"/>
        <geometry>
          <mesh filename="package://aero_description/meshes/typeC_lifter/lifter_base.dae" scale="1 1 1" />
        </geometry>
      </visual>
      <collision>
        <origin xyz="0 0 0" rpy="0 -0 0"/>
        <geometry>
          <mesh filename="package://aero_description/meshes/typeC_lifter/lifter_base.dae" scale="1 1 1" />
        </geometry>
      </collision>
      <inertial>
        <mass value="1.074" />
        <origin xyz="0.004 0.0 0.044" rpy="0 0 0"/>
        <inertia ixx="0.004" ixy="0.0" ixz="0.0" iyy="0.001" iyz="0.0" izz="0.002"/>
      </inertial>
    </link>
    <xacro:gazebo_link_reference link_name="${base_link}" />

    <link name="leg_shank_link">
      <visual>
        <origin xyz="0.0 0.0 0" rpy="3.1415 -0 0"/>
        <geometry>
          <mesh filename="package://aero_description/meshes/typeC_lifter/lifter_bone.dae" scale="1 1 1" />
        </geometry>
      </visual>
      <collision>
        <origin xyz="0.0 0.0 0" rpy="3.1415 -0 0"/>
        <geometry>
          <mesh filename="package://aero_description/meshes/typeC_lifter/lifter_bone.dae" scale="1 1 1" />
        </geometry>
      </collision>
      <inertial>
        <mass value="1.221" />
        <origin xyz="0.003 0 0.107" rpy="0 0 0"/>
        <inertia ixx="0.006" ixy="0.0" ixz="0.0" iyy="0.006" iyz="0.0" izz="0.002"/>
      </inertial>
    </link>
    <xacro:gazebo_link_reference link_name="leg_shank_link" />

    <link name="leg_knee_link">
      <visual>
        <origin xyz="0.0 0.0 0" rpy="3.1415 -0 0"/>
        <geometry>
          <mesh filename="package://aero_description/meshes/typeC_lifter/lifter_knee.dae" scale="1 1 1" />
        </geometry>
      </visual>
      <collision>
        <origin xyz="0.0 0.0 0" rpy="3.1415 -0 0"/>
        <geometry>
          <mesh filename="package://aero_description/meshes/typeC_lifter/lifter_knee.dae" scale="1 1 1" />
        </geometry>
      </collision>
      <inertial>
        <mass value="0.829" />
        <origin xyz="-0.004 0.0 0.06" rpy="0 0 0"/>
        <inertia ixx="0.003" ixy="0.0" ixz="0.0" iyy="0.003" iyz="0.0" izz="0.001"/>
      </inertial>
    </link>
    <xacro:gazebo_link_reference link_name="leg_knee_link" />

    <link name="leg_thigh_link">
      <visual>
        <origin xyz="0 0 0.25" rpy="0 0 0"/>
        <geometry>
          <mesh filename="package://aero_description/meshes/typeC_lifter/lifter_bone.dae" scale="1 1 1" />
        </geometry>
      </visual>
      <collision>
        <origin xyz="0 0 0.25" rpy="0 0 0"/>
        <geometry>
          <mesh filename="package://aero_description/meshes/typeC_lifter/lifter_bone.dae" scale="1 1 1" />
        </geometry>
      </collision>
      <inertial>
        <mass value="1.221" />
        <mass value="0" />
        <origin xyz="0.003 0 0.143" rpy="0 0 0"/>
        <inertia ixx="0.006" ixy="0.0" ixz="0.0" iyy="0.006" iyz="0.0" izz="0.002"/>
      </inertial>
    </link>
    <xacro:gazebo_link_reference link_name="leg_thigh_link" />

    <link name="leg_base_link">
      <visual>
        <origin xyz="0 0 0.05" rpy="3.1415 0 0"/>
        <geometry>
          <mesh filename="package://aero_description/meshes/typeC_lifter/lifter_base.dae" scale="1 1 1" />
        </geometry>
      </visual>
      <collision>
        <origin xyz="0 0 0.05" rpy="3.1415 0 0"/>
        <geometry>
          <mesh filename="package://aero_description/meshes/typeC_lifter/lifter_base.dae" scale="1 1 1" />
        </geometry>
      </collision>
      <inertial>
        <mass value="1.074" />
        <origin xyz="0.004 0.0 -0.044" rpy="0 0 0"/>
        <inertia ixx="0.002" ixy="0.0" ixz="0.0" iyy="0.001" iyz="0.0" izz="0.002"/>
      </inertial>
    </link>
    <xacro:gazebo_link_reference link_name="leg_base_link" />

    <link name="lifter_top_link">
      <visual>
        <origin xyz="0 0 0" rpy="0 -0 0"/>
        <geometry>
          <mesh filename="package://aero_description/meshes/typeC_lifter/lifter_top.dae" scale="1 1 1" />
        </geometry>
      </visual>
      <collision>
        <origin xyz="0 0 0" rpy="0 -0 0"/>
        <geometry>
          <mesh filename="package://aero_description/meshes/typeC_lifter/lifter_top.dae" scale="1 1 1" />
        </geometry>
      </collision>
      <inertial>
        <mass value="0.82" />
        <origin xyz="-0.002 0.0 0.0" rpy="0 0 0"/>
        <inertia ixx="0.003" ixy="0.0" ixz="0.0" iyy="0.002" iyz="0.0" izz="0.005"/>
      </inertial>
    </link>
    <xacro:gazebo_link_reference link_name="lifter_top_link" />

    <joint name="lifter_top_connector" type="fixed">
      <parent link="leg_base_link"/>
      <child  link="lifter_top_link"/>
      <origin xyz="0 0 0.055" rpy="0 0 0"/>
    </joint>

    <joint name="knee_joint_mimic" type="revolute">
      <parent link="leg_thigh_link"/>
      <child link="leg_base_link"/>
      <origin xyz="0 0 0.25" rpy="0 0 0"/>
      <axis   xyz="0 -1 0"/>
      <mimic joint="knee_joint" multiplier="-1" offset="0"/>
      <limit effort="10000" upper="1.5707" lower="0" velocity="1.5"/> <!-- just invert of knee_joint -->
    </joint>

    <joint name="knee_joint" type="revolute"> <!-- rename "knee_joint_thigh_dummy" -->
      <parent link="leg_knee_link"/>
      <child  link="leg_thigh_link"/>
      <origin xyz="0 0 0.12" rpy="0 0 0"/>
      <axis xyz="0 -1 0"/>
      <limit effort="10000" lower="-1.5707" upper="0" velocity="1.5"/>
    </joint>
    <xacro:gazebo_transmission joint_name="knee_joint" />

    <joint name="ankle_joint" type="revolute">
      <parent link="${base_link}"/>
      <child  link="leg_shank_link"/>
      <origin xyz="0 0 0.05" rpy="0 0 0"/>
      <axis   xyz="0 -1 0"/>
      <limit effort="10000" lower="0" upper="1.5707" velocity="1.5" />
      <dynamics damping="0.2" friction="0" />
    </joint>
    <xacro:gazebo_transmission joint_name="ankle_joint" />

<!--- mimic joints -->
<!-- requried -->
    <joint name="ankle_joint_mimic" type="revolute">
      <parent link="leg_shank_link"/>
      <child  link="leg_knee_link"/>
      <origin xyz="0 0 0.25" rpy="0 0 0"/>
      <axis   xyz="0 -1 0"/>
      <mimic joint="ankle_joint" multiplier="-1" offset="0" />
      <limit effort="10000" upper="0" lower="-1.5707" velocity="1.5" /> <!-- just invert of ankle_joint -->
    </joint>

<!-- redundant -->
    <link name="leg_shank_link_dummy">
      <visual>
        <geometry>
          <mesh filename="package://aero_description/meshes/typeC_lifter/lifter_bone_dummy.dae" scale="1 1 1" />
        </geometry>
        <origin xyz="0 0 0.25" rpy="0 0 0"/>
      </visual>
      <inertial> <!-- for gazebo visualization -->
        <mass value="0.376"/>
        <origin rpy="0 0 0" xyz="0.011 0.0 0.129"/>
        <inertia ixx="0.0025" ixy="0.0" ixz="0.0021" iyy="0.008" iyz="0" izz="0.0005"/>
      </inertial>
    </link>
    <link name="leg_thigh_link_dummy">
      <visual>
        <geometry>
          <mesh filename="package://aero_description/meshes/typeC_lifter/lifter_bone_dummy.dae" scale="1 1 1" />
        </geometry>
        <origin xyz="0 0 0.25" rpy="0 0 0"/>
      </visual>
      <inertial> <!-- for gazebo visualization -->
        <mass value="0.376"/>
        <origin rpy="0 0 0" xyz="0.011 0.0 0.129"/>
        <inertia ixx="0.0025" ixy="0.0" ixz="0.0021" iyy="0.008" iyz="0" izz="0.0005"/>
      </inertial>
    </link>

    <joint name="ankle_joint_dummy" type="continuous">
      <parent link="${base_link}"/>
      <child link="leg_shank_link_dummy"/>
      <origin xyz="0.03182 0 0.08182" rpy="0 0 0"/>
      <axis xyz="0 -1 0"/>
      <mimic joint="ankle_joint" multiplier="1" offset="0" />
    </joint>
    <joint name="knee_joint_dummy" type="continuous">
      <parent link="leg_knee_link"/>
      <child link="leg_thigh_link_dummy"/>
      <origin xyz="0.03182 0 0.08818" rpy="0 0 0"/>
      <axis xyz="0 1 0"/>
      <mimic joint="knee_joint" multiplier="-1" offset="0" />
    </joint>

  </xacro:macro>

</robot>
